<?xml version="1.0" ?>

<robot name="mobile_robot" xmlns:xacro="http://ros.org/wiki/xacro">
    
    <link name="base_link">
        
        <inertial>
            <origin xyz="0.0 0.0 0.0" rpy="0.0 0.0 0.0"/>
            <mass value="0.2"/>
            <inertia ixx="0.00167" ixy="0.0" ixz="0.0" iyy="0.00167" iyz="0.0" izz="0.003"/>
        </inertial>
        
        <visual>
            <origin xyz="0.0 0.0 0.0" rpy="0.0 0.0 0.0"/>
            <geometry>
                <box size="0.3 0.3 0.1"/>
            </geometry>
        </visual>
        
        <collision>
            <origin xyz="0.0 0.0 0.0" rpy="0.0 0.0 0.0"/>
            <geometry>
                <box size="0.3 0.3 0.1"/>
            </geometry>
        </collision>
        
    </link>

    <joint name="base_2_left_wheel" type="continuous">
        <origin xyz="0.0 0.161 0.0" rpy="0.0 0.0 0.0"/>
        <parent link="base_link"/>
        <child link="left_wheel"/>
        <axis xyz="0.0 1.0 0.0"/>
    </joint>
    
    <link name="left_wheel">
        
        <inertial>
            <origin xyz="0.0 0.0 0.0" rpy="1.5708 0.0 0.0"/>
            <mass value="0.01"/>
            <inertia ixx="0.00001258" ixy="0.0" ixz="0.0" iyy="0.00001258" iyz="0.0" izz="0.0000245"/>
        </inertial>
        
        <visual name="">
            <origin xyz="0.0 0.0 0.0" rpy="1.5708 0.0 0.0"/>
            <geometry>
                <cylinder radius="0.07" length="0.02"/> 
            </geometry>
        </visual>
        
        <collision>
            <origin xyz="0.0 0.0 0.0" rpy="1.5708 0.0 0.0"/>
            <geometry>
                <cylinder radius="0.07" length="0.02"/>
            </geometry>
        </collision>

    </link>

    <joint name="base_2_right_wheel" type="continuous">
        <origin xyz="0.0 -0.161 0.0" rpy="0.0 0.0 0.0"/>
        <parent link="base_link"/>
        <child link="right_wheel"/>
        <axis xyz="0.0 1.0 0.0"/>
    </joint>
    
    <link name="right_wheel">
        
        <inertial>
            <origin xyz="0.0 0.0 0.0" rpy="1.5708 0.0 0.0"/>
            <mass value="0.01"/>
            <inertia ixx="0.00001258" ixy="0.0" ixz="0.0" iyy="0.00001258" iyz="0.0" izz="0.0000245"/>
        </inertial>
        
        <visual name="">
            <origin xyz="0.0 0.0 0.0" rpy="1.5708 0.0 0.0"/>
            <geometry>
                <cylinder radius="0.07" length="0.02"/> 
            </geometry>
        </visual>
        
        <collision>
            <origin xyz="0.0 0.0 0.0" rpy="1.5708 0.0 0.0"/>
            <geometry>
                <cylinder radius="0.07" length="0.02"/>
            </geometry>
        </collision>

    </link>

<!-- Odomtery and differential -->

    <gazebo>
        <plugin name="differential_drive_controller" filename="libgazebo_ros_diff_drive.so">
            <updateRate>100</updateRate>
            <leftJoint>base_2_left_wheel</leftJoint>
            <rightJoint>base_2_right_wheel</rightJoint>
            <wheelSeparation>0.322</wheelSeparation>
            <wheelDiameter>0.14</wheelDiameter>
            <wheelAcceleration>1.0</wheelAcceleration>
            <wheelTorque>20</wheelTorque>
            <commandTopic>mobile_robot/cmd_vel</commandTopic>
            <odometryTopic>mobile_robot/odom</odometryTopic>
            <odometryFrame>odom</odometryFrame>
            <robotBaseFrame>base_link</robotBaseFrame>
            <odometrySource>1</odometrySource>
            <publishWheelTF>true</publishWheelTF>
            <publishOdom>true</publishOdom>
            <publishWheelJointState>true</publishWheelJointState>
            <legacyMode>false</legacyMode>
        </plugin>
    </gazebo>

<!-- IMU -->

    <link name="imu_link">
        
        <inertial>
            <mass value="0.0"/>
            <inertia ixx="0.0" ixy="0.0" ixz="0.0" iyy="0.0" iyz="0.0" izz="0.0"/>
        </inertial>
        
        <visual>
            <origin xyz="0.0 0.0 0.0" rpy="0.0 0.0 0.0"/>
            <geometry>
                <box size="0.01 0.01 0.01"/>
            </geometry>
        </visual>

        <collision>
            <origin xyz="0.0 0.0 0.0" rpy="0.0 0.0 0.0"/>
            <geometry>
                <box size="0.01 0.01 0.01"/>
            </geometry>
        </collision>

    </link>

    <joint name="base_link_2_imu" type="fixed">
        <origin xyz="0.0 0.0 0.05" rpy="0.0 0.0 0.0"/>
        <parent link="base_link"/>
        <child link="imu_link"/>
    </joint>

    <gazebo reference="imu_link">
        <gravity>true</gravity>
        <sensor name="imu_sensor" type="imu">
            <always_on>true</always_on>
            <update_rate>100</update_rate>
            <visualize>true</visualize>
            <topic>__default_topic__</topic>
            <plugin filename="libgazebo_ros_imu_sensor.so" name="imu_plugin">
                <topicName>mobile_robot/imu</topicName>
                <bodyName>imu_link</bodyName>
                <updateRateHZ>10.0</updateRateHZ>
                <gaussianNoise>0.0</gaussianNoise>
                <xyzOffset>0 0 0</xyzOffset>
                <rpyOffset>0 0 0</rpyOffset>
                <frameName>imu_link</frameName>
                <initialOrientationAsReference>false</initialOrientationAsReference>
            </plugin>
            <pose>0 0 0 0 0 0</pose>
        </sensor>
    </gazebo>

<!-- Laser scanner -->

    <link name="laser_scan_link">
        <inertial>
            <mass value="0.17"/>
            <inertia ixx="0.0001926" ixy="0.0" ixz="0.0" iyy="0.000122" iyz="0.0" izz="0.0002129"/>
        </inertial>
        <visual>
            <geometry>
                <mesh filename="package://robot_models_description/meshes/rplidar.dae"/>
            </geometry>
        </visual>
        <collision>
            <geometry>
                <box size="0.071 0.1 0.06"/>
            </geometry>
        </collision>
    </link>

    <joint name="base_link_2_laser_scan" type="fixed">
        <origin xyz="0.0 0.0 0.09" rpy="0.0 0.0 0.0"/>
        <parent link="base_link"/>
        <child link="laser_scan_link"/>
    </joint>

    <gazebo reference="laser_scan_link">
        <sensor type="ray" name="head_hokuyo_sensor">
            <update_rate>62</update_rate>
            <visualize>false</visualize>
            <ray>
                <scan>
                    <horizontal>
                        <samples>640</samples>
                        <resolution>1</resolution>
                        <min_angle>-3.1415926535897931</min_angle>
                        <max_angle>3.1415926535897931</max_angle>
                    </horizontal>
                </scan>
                <range>
                    <min>0.164</min>
                    <max>12</max>
                    <resolution>0.01</resolution>
                </range>
                <noise>
                    <type>gaussian</type>
                    <mean>0.0</mean>
                    <stddev>0.01</stddev>
                </noise>
            </ray>

            <plugin name="gazebo_ros_head_hokuyo_controller" filename="libgazebo_ros_laser.so">
                <topicName>/mobile_robot/lase_scan</topicName>
                <frameName>laser_scan_link</frameName>
                <min_range>0.164</min_range>
                <max_range>12</max_range>
                <gaussianNoise>0.008</gaussianNoise>
            </plugin>

        </sensor>
    </gazebo> 
    
<!-- Depth Camera -->
    <link name="camera_oakd_link">
        <inertial>
            <mass value="0.061"/>
            <inertia ixx="0.00000202475" ixy="0.0" ixz="0.0"
	             iyy="0.00001527320" iyz="0.0" izz="0.00001605536"/>
        </inertial>
        <visual>
            <geometry>
                <mesh filename="package://robot_models_description/meshes/oak_d_camera.dae"/>
            </geometry>
        </visual>
        <collision>
            <geometry>
                <box size="0.0225 0.097 0.03"/>
            </geometry>
        </collision>
    </link>

    <joint name="base_link_2_camera" type="fixed">
        <origin xyz="0.0 0.0 0.15" rpy="0.0 0.0 0.0"/>
        <parent link="base_link"/>
        <child link="camera_oakd_link"/>
    </joint>

    <gazebo reference="camera_oakd_link">
        <sensor name="depth_kinect_camera" type="depth">
            <update_rate>20</update_rate>
            <camera>
                <horizontal_fov>1.047198</horizontal_fov>
                <image>
                    <width>640</width>
                    <height>480</height>
                    <format>R8G8B8</format>
                </image>
                <clip>
                    <near>0.05</near>
                    <far>3</far>
                </clip>
            </camera>

            <plugin name="depth_camera_controller" filename="libgazebo_ros_openni_kinect.so">
                <baseline>0.2</baseline>
                <alwaysOn>true</alwaysOn>
                <updateRate>1.0</updateRate>
                <cameraName>depth_kinect_camera</cameraName>
                <imageTopicName>/mobile_robot/color/image_raw</imageTopicName>
                <cameraInfoTopicName>/mobile_robot/color/camera_info</cameraInfoTopicName>
                <depthImageTopicName>/mobile_robot/depth/image_raw</depthImageTopicName>
                <depthImageInfoTopicName>/mobile_robot/depth/camera_info</depthImageInfoTopicName>
                <pointCloudTopicName>/mobile_robot/depth/points</pointCloudTopicName>
                <frameName>camera_oakd_link</frameName>
                <pointCloudCutoff>0.5</pointCloudCutoff>
                <pointCloudCutoffMax>3.0</pointCloudCutoffMax>
                <distortionK1>0.00000001</distortionK1>
                <distortionK2>0.00000001</distortionK2>
                <distortionK3>0.00000001</distortionK3>
                <distortionT1>0.00000001</distortionT1>
                <distortionT2>0.00000001</distortionT2>
                <CxPrime>0</CxPrime>
                <Cx>0</Cx>
                <Cy>0</Cy>
                <focalLength>0</focalLength>
                <hackBaseline>0</hackBaseline>
            </plugin>
        </sensor>
    </gazebo>


</robot>